2018-07-29 23:46:32,260 [WARNING] django.request: Not Found: /api/v1/g
2018-07-29 23:47:09,174 [WARNING] django.request: Not Found: /api/v1/g
2018-07-30 00:00:30,716 [ERROR] django.request: Internal Server Error: /api/v1/get_dog/7b49bbc6-d87b-42ce-87d5-fa512c2855f0
2018-07-31 20:31:03,519 [WARNING] django.request: Not Found: /api/v1/get_dog/7b49bbc6-d87b-42ce-87d5-fa512c2855f0
2018-07-31 20:31:34,493 [WARNING] django.request: Not Found: /api/v1/get_dog/fe6441f7-9d7d-4222-90bd-ac9a2947bf44
2018-07-31 20:32:01,234 [WARNING] django.request: Not Found: /api/v1/dog/fe6441f7-9d7d-4222-90bd-ac9a2947bf41
2018-07-31 21:19:20,512 [ERROR] django.request: Internal Server Error: /api/v1/create_user
Traceback (most recent call last):
  File "/usr/local/lib/python3.7/site-packages/django/core/handlers/exception.py", line 35, in inner
    response = get_response(request)
  File "/usr/local/lib/python3.7/site-packages/django/core/handlers/base.py", line 128, in _get_response
    response = self.process_exception_by_middleware(e, request)
  File "/usr/local/lib/python3.7/site-packages/django/core/handlers/base.py", line 126, in _get_response
    response = wrapped_callback(request, *callback_args, **callback_kwargs)
  File "/usr/local/lib/python3.7/site-packages/django/views/decorators/csrf.py", line 54, in wrapped_view
    return view_func(*args, **kwargs)
  File "/usr/local/lib/python3.7/site-packages/django/views/decorators/http.py", line 40, in inner
    return func(request, *args, **kwargs)
  File "/Users/kevindeems/Desktop/codingTests/python_learning/dog_server/dog_info/views.py", line 46, in create_user
    return abstract_request.start(Handler.create_user_logic)
  File "/Users/kevindeems/Desktop/codingTests/python_learning/dog_server/dog_info/resources/router.py", line 198, in start
    response = func(self, model=self.model, body=body, id=self.id)
TypeError: create_user_logic() got an unexpected keyword argument 'id'
