2018-07-29 23:46:32,260 [WARNING] django.request: Not Found: /api/v1/g
2018-07-29 23:47:09,174 [WARNING] django.request: Not Found: /api/v1/g
2018-07-30 00:00:30,716 [ERROR] django.request: Internal Server Error: /api/v1/get_dog/7b49bbc6-d87b-42ce-87d5-fa512c2855f0
2018-07-31 20:31:03,519 [WARNING] django.request: Not Found: /api/v1/get_dog/7b49bbc6-d87b-42ce-87d5-fa512c2855f0
2018-07-31 20:31:34,493 [WARNING] django.request: Not Found: /api/v1/get_dog/fe6441f7-9d7d-4222-90bd-ac9a2947bf44
2018-07-31 20:32:01,234 [WARNING] django.request: Not Found: /api/v1/dog/fe6441f7-9d7d-4222-90bd-ac9a2947bf41
2018-07-31 21:19:20,512 [ERROR] django.request: Internal Server Error: /api/v1/create_user
Traceback (most recent call last):
  File "/usr/local/lib/python3.7/site-packages/django/core/handlers/exception.py", line 35, in inner
    response = get_response(request)
  File "/usr/local/lib/python3.7/site-packages/django/core/handlers/base.py", line 128, in _get_response
    response = self.process_exception_by_middleware(e, request)
  File "/usr/local/lib/python3.7/site-packages/django/core/handlers/base.py", line 126, in _get_response
    response = wrapped_callback(request, *callback_args, **callback_kwargs)
  File "/usr/local/lib/python3.7/site-packages/django/views/decorators/csrf.py", line 54, in wrapped_view
    return view_func(*args, **kwargs)
  File "/usr/local/lib/python3.7/site-packages/django/views/decorators/http.py", line 40, in inner
    return func(request, *args, **kwargs)
  File "/Users/kevindeems/Desktop/codingTests/python_learning/dog_server/dog_info/views.py", line 46, in create_user
    return abstract_request.start(Handler.create_user_logic)
  File "/Users/kevindeems/Desktop/codingTests/python_learning/dog_server/dog_info/resources/router.py", line 198, in start
    response = func(self, model=self.model, body=body, id=self.id)
TypeError: create_user_logic() got an unexpected keyword argument 'id'
2018-08-01 02:25:21,811 [ERROR] django.request: Internal Server Error: /api/v1/dog/fe6441f7-9d7d-4222-90bd-ac9a2947bf44
Traceback (most recent call last):
  File "/Users/kevindeems/Desktop/codingTests/python_learning/dog_server/dog_info/resources/router.py", line 317, in dispatch
    data = cls.model_data[model]
KeyError: <class 'dog_info.models.Dog'>

During handling of the above exception, another exception occurred:

Traceback (most recent call last):
  File "/usr/local/lib/python3.7/site-packages/django/core/handlers/exception.py", line 35, in inner
    response = get_response(request)
  File "/usr/local/lib/python3.7/site-packages/django/core/handlers/base.py", line 128, in _get_response
    response = self.process_exception_by_middleware(e, request)
  File "/usr/local/lib/python3.7/site-packages/django/core/handlers/base.py", line 126, in _get_response
    response = wrapped_callback(request, *callback_args, **callback_kwargs)
  File "/usr/local/lib/python3.7/site-packages/django/views/decorators/csrf.py", line 54, in wrapped_view
    return view_func(*args, **kwargs)
  File "/Users/kevindeems/Desktop/codingTests/python_learning/dog_server/dog_info/resources/router.py", line 348, in dispatch
    return JsonResponse(error, status=status, json_dumps_params={"indent": 2})
  File "/usr/local/lib/python3.7/site-packages/django/http/response.py", line 509, in __init__
    data = json.dumps(data, cls=encoder, **json_dumps_params)
  File "/usr/local/Cellar/python/3.7.0/Frameworks/Python.framework/Versions/3.7/lib/python3.7/json/__init__.py", line 238, in dumps
    **kw).encode(obj)
  File "/usr/local/Cellar/python/3.7.0/Frameworks/Python.framework/Versions/3.7/lib/python3.7/json/encoder.py", line 201, in encode
    chunks = list(chunks)
  File "/usr/local/Cellar/python/3.7.0/Frameworks/Python.framework/Versions/3.7/lib/python3.7/json/encoder.py", line 431, in _iterencode
    yield from _iterencode_dict(o, _current_indent_level)
  File "/usr/local/Cellar/python/3.7.0/Frameworks/Python.framework/Versions/3.7/lib/python3.7/json/encoder.py", line 405, in _iterencode_dict
    yield from chunks
  File "/usr/local/Cellar/python/3.7.0/Frameworks/Python.framework/Versions/3.7/lib/python3.7/json/encoder.py", line 438, in _iterencode
    o = _default(o)
  File "/usr/local/lib/python3.7/site-packages/django/core/serializers/json.py", line 104, in default
    return super().default(o)
  File "/usr/local/Cellar/python/3.7.0/Frameworks/Python.framework/Versions/3.7/lib/python3.7/json/encoder.py", line 179, in default
    raise TypeError(f'Object of type {o.__class__.__name__} '
TypeError: Object of type ModelBase is not JSON serializable
2018-08-01 02:28:00,568 [ERROR] django.request: Internal Server Error: /api/v1/dog/fe6441f7-9d7d-4222-90bd-ac9a2947bf44
Traceback (most recent call last):
  File "/usr/local/lib/python3.7/site-packages/django/db/models/fields/__init__.py", line 2363, in to_python
    return uuid.UUID(value)
  File "/usr/local/Cellar/python/3.7.0/Frameworks/Python.framework/Versions/3.7/lib/python3.7/uuid.py", line 157, in __init__
    hex = hex.replace('urn:', '').replace('uuid:', '')
AttributeError: 'dict' object has no attribute 'replace'

During handling of the above exception, another exception occurred:

Traceback (most recent call last):
  File "/Users/kevindeems/Desktop/codingTests/python_learning/dog_server/dog_info/resources/router.py", line 319, in dispatch
    return handler_method(request, model, *args, data)
  File "/Users/kevindeems/Desktop/codingTests/python_learning/dog_server/dog_info/resources/router.py", line 293, in get
    return abstract_request.start(Handler.get)
  File "/Users/kevindeems/Desktop/codingTests/python_learning/dog_server/dog_info/resources/router.py", line 149, in start
    response = func(self, self.model, self.id)
  File "/Users/kevindeems/Desktop/codingTests/python_learning/dog_server/dog_info/resources/router.py", line 192, in get
    if len(items) == 0:
  File "/usr/local/lib/python3.7/site-packages/django/db/models/query.py", line 254, in __len__
    self._fetch_all()
  File "/usr/local/lib/python3.7/site-packages/django/db/models/query.py", line 1179, in _fetch_all
    self._result_cache = list(self._iterable_class(self))
  File "/usr/local/lib/python3.7/site-packages/django/db/models/query.py", line 53, in __iter__
    results = compiler.execute_sql(chunked_fetch=self.chunked_fetch, chunk_size=self.chunk_size)
  File "/usr/local/lib/python3.7/site-packages/django/db/models/sql/compiler.py", line 1055, in execute_sql
    sql, params = self.as_sql()
  File "/usr/local/lib/python3.7/site-packages/django/db/models/sql/compiler.py", line 461, in as_sql
    where, w_params = self.compile(self.where) if self.where is not None else ("", [])
  File "/usr/local/lib/python3.7/site-packages/django/db/models/sql/compiler.py", line 393, in compile
    sql, params = node.as_sql(self, self.connection)
  File "/usr/local/lib/python3.7/site-packages/django/db/models/sql/where.py", line 80, in as_sql
    sql, params = compiler.compile(child)
  File "/usr/local/lib/python3.7/site-packages/django/db/models/sql/compiler.py", line 393, in compile
    sql, params = node.as_sql(self, self.connection)
  File "/usr/local/lib/python3.7/site-packages/django/db/models/lookups.py", line 161, in as_sql
    rhs_sql, rhs_params = self.process_rhs(compiler, connection)
  File "/usr/local/lib/python3.7/site-packages/django/db/models/lookups.py", line 260, in process_rhs
    return super().process_rhs(compiler, connection)
  File "/usr/local/lib/python3.7/site-packages/django/db/models/lookups.py", line 93, in process_rhs
    return self.get_db_prep_lookup(value, connection)
  File "/usr/local/lib/python3.7/site-packages/django/db/models/lookups.py", line 187, in get_db_prep_lookup
    [get_db_prep_value(value, connection, prepared=True)]
  File "/usr/local/lib/python3.7/site-packages/django/db/models/fields/__init__.py", line 2354, in get_db_prep_value
    value = self.to_python(value)
  File "/usr/local/lib/python3.7/site-packages/django/db/models/fields/__init__.py", line 2368, in to_python
    params={'value': value},
django.core.exceptions.ValidationError: ["'{'error': 'Bad request', 'request_schema': {'name': 'Rocky (string)', 'breed': 'Golden Retriever (string)', 'favorite_activity': 'Running for frisbees (string)', 'sex': 'M/F/X (character)', 'birth_day': '06/09/1956 (mm/dd/yyyy)'}}' is not a valid UUID."]

During handling of the above exception, another exception occurred:

Traceback (most recent call last):
  File "/usr/local/lib/python3.7/site-packages/django/http/response.py", line 49, in __init__
    self.status_code = int(status)
ValueError: invalid literal for int() with base 10: 'invalid'

During handling of the above exception, another exception occurred:

Traceback (most recent call last):
  File "/usr/local/lib/python3.7/site-packages/django/core/handlers/exception.py", line 35, in inner
    response = get_response(request)
  File "/usr/local/lib/python3.7/site-packages/django/core/handlers/base.py", line 128, in _get_response
    response = self.process_exception_by_middleware(e, request)
  File "/usr/local/lib/python3.7/site-packages/django/core/handlers/base.py", line 126, in _get_response
    response = wrapped_callback(request, *callback_args, **callback_kwargs)
  File "/usr/local/lib/python3.7/site-packages/django/views/decorators/csrf.py", line 54, in wrapped_view
    return view_func(*args, **kwargs)
  File "/Users/kevindeems/Desktop/codingTests/python_learning/dog_server/dog_info/resources/router.py", line 348, in dispatch
    return JsonResponse(error, status=status, json_dumps_params={"indent": 2})
  File "/usr/local/lib/python3.7/site-packages/django/http/response.py", line 510, in __init__
    super().__init__(content=data, **kwargs)
  File "/usr/local/lib/python3.7/site-packages/django/http/response.py", line 283, in __init__
    super().__init__(*args, **kwargs)
  File "/usr/local/lib/python3.7/site-packages/django/http/response.py", line 51, in __init__
    raise TypeError('HTTP status code must be an integer.')
TypeError: HTTP status code must be an integer.
2018-08-02 12:04:12,461 [WARNING] django.request: Not Found: /favicon.ico
2018-08-02 12:23:24,907 [WARNING] django.request: Not Found: /api/v1/shelter
2018-08-03 17:21:18,017 [ERROR] django.request: Internal Server Error: /api/v1/dog/fe6441f7-9d7d-4222-90bd-ac9a2947bf44
Traceback (most recent call last):
  File "/usr/local/lib/python3.7/site-packages/django/core/handlers/exception.py", line 35, in inner
    response = get_response(request)
  File "/usr/local/lib/python3.7/site-packages/django/core/handlers/base.py", line 128, in _get_response
    response = self.process_exception_by_middleware(e, request)
  File "/usr/local/lib/python3.7/site-packages/django/core/handlers/base.py", line 126, in _get_response
    response = wrapped_callback(request, *callback_args, **callback_kwargs)
  File "/usr/local/lib/python3.7/site-packages/django/views/decorators/csrf.py", line 54, in wrapped_view
    return view_func(*args, **kwargs)
  File "/Users/kevindeems/Desktop/codingTests/python_learning/dog_server/dog_info/resources/router.py", line 82, in dispatch
    return handler_method(request, model, **kwargs)
  File "/Users/kevindeems/Desktop/codingTests/python_learning/dog_server/dog_info/resources/router.py", line 49, in get
    return abstract_request.start(Handler.get)
  File "/Users/kevindeems/Desktop/codingTests/python_learning/dog_server/dog_info/resources/handler.py", line 146, in start
    body = json.loads(self.request.body)
  File "/usr/local/Cellar/python/3.7.0/Frameworks/Python.framework/Versions/3.7/lib/python3.7/json/__init__.py", line 348, in loads
    return _default_decoder.decode(s)
  File "/usr/local/Cellar/python/3.7.0/Frameworks/Python.framework/Versions/3.7/lib/python3.7/json/decoder.py", line 337, in decode
    obj, end = self.raw_decode(s, idx=_w(s, 0).end())
  File "/usr/local/Cellar/python/3.7.0/Frameworks/Python.framework/Versions/3.7/lib/python3.7/json/decoder.py", line 355, in raw_decode
    raise JSONDecodeError("Expecting value", s, err.value) from None
json.decoder.JSONDecodeError: Expecting value: line 1 column 1 (char 0)
2018-08-03 17:22:42,520 [ERROR] django.request: Internal Server Error: /api/v1/dog/fe6441f7-9d7d-4222-90bd-ac9a2947bf44
Traceback (most recent call last):
  File "/usr/local/lib/python3.7/site-packages/django/core/handlers/exception.py", line 35, in inner
    response = get_response(request)
  File "/usr/local/lib/python3.7/site-packages/django/core/handlers/base.py", line 128, in _get_response
    response = self.process_exception_by_middleware(e, request)
  File "/usr/local/lib/python3.7/site-packages/django/core/handlers/base.py", line 126, in _get_response
    response = wrapped_callback(request, *callback_args, **callback_kwargs)
  File "/usr/local/lib/python3.7/site-packages/django/views/decorators/csrf.py", line 54, in wrapped_view
    return view_func(*args, **kwargs)
  File "/Users/kevindeems/Desktop/codingTests/python_learning/dog_server/dog_info/resources/router.py", line 82, in dispatch
    return handler_method(request, model, **kwargs)
  File "/Users/kevindeems/Desktop/codingTests/python_learning/dog_server/dog_info/resources/router.py", line 49, in get
    return abstract_request.start(Handler.get)
  File "/Users/kevindeems/Desktop/codingTests/python_learning/dog_server/dog_info/resources/handler.py", line 156, in start
    body=body, id=self.id)
UnboundLocalError: local variable 'body' referenced before assignment
2018-08-03 17:26:05,546 [ERROR] django.request: Internal Server Error: /api/v1/dog/fe6441f7-9d7d-4222-90bd-ac9a2947bf44
Traceback (most recent call last):
  File "/usr/local/lib/python3.7/site-packages/django/core/handlers/exception.py", line 35, in inner
    response = get_response(request)
  File "/usr/local/lib/python3.7/site-packages/django/core/handlers/base.py", line 128, in _get_response
    response = self.process_exception_by_middleware(e, request)
  File "/usr/local/lib/python3.7/site-packages/django/core/handlers/base.py", line 126, in _get_response
    response = wrapped_callback(request, *callback_args, **callback_kwargs)
  File "/usr/local/lib/python3.7/site-packages/django/views/decorators/csrf.py", line 54, in wrapped_view
    return view_func(*args, **kwargs)
  File "/Users/kevindeems/Desktop/codingTests/python_learning/dog_server/dog_info/resources/router.py", line 82, in dispatch
    return handler_method(request, model, **kwargs)
  File "/Users/kevindeems/Desktop/codingTests/python_learning/dog_server/dog_info/resources/router.py", line 49, in get
    return abstract_request.start(Handler.get)
  File "/Users/kevindeems/Desktop/codingTests/python_learning/dog_server/dog_info/resources/handler.py", line 163, in start
    response = func(self, func_params)
TypeError: get() missing 1 required positional argument: 'id'
2018-08-03 17:29:34,912 [WARNING] django.request: Not Found: /api/v1/dog/fe6441f7-9d7d-4222-90bd-ac9a2947bf44
2018-08-03 17:30:50,778 [WARNING] django.request: Not Found: /api/v1/shelter/192beef5-6fd8-44c0-a0df-1e0cad165774
2018-08-03 17:31:35,305 [ERROR] django.request: Internal Server Error: /api/v1/dog
Traceback (most recent call last):
  File "/usr/local/lib/python3.7/site-packages/django/core/handlers/exception.py", line 35, in inner
    response = get_response(request)
  File "/usr/local/lib/python3.7/site-packages/django/core/handlers/base.py", line 128, in _get_response
    response = self.process_exception_by_middleware(e, request)
  File "/usr/local/lib/python3.7/site-packages/django/core/handlers/base.py", line 126, in _get_response
    response = wrapped_callback(request, *callback_args, **callback_kwargs)
  File "/usr/local/lib/python3.7/site-packages/django/views/decorators/csrf.py", line 54, in wrapped_view
    return view_func(*args, **kwargs)
  File "/Users/kevindeems/Desktop/codingTests/python_learning/dog_server/dog_info/resources/router.py", line 82, in dispatch
    return handler_method(request, model, **kwargs)
TypeError: post() missing 1 required positional argument: 'data'
2018-08-03 17:33:20,198 [ERROR] django.request: Internal Server Error: /api/v1/dog
Traceback (most recent call last):
  File "/usr/local/lib/python3.7/site-packages/django/core/handlers/exception.py", line 35, in inner
    response = get_response(request)
  File "/usr/local/lib/python3.7/site-packages/django/core/handlers/base.py", line 128, in _get_response
    response = self.process_exception_by_middleware(e, request)
  File "/usr/local/lib/python3.7/site-packages/django/core/handlers/base.py", line 126, in _get_response
    response = wrapped_callback(request, *callback_args, **callback_kwargs)
  File "/usr/local/lib/python3.7/site-packages/django/views/decorators/csrf.py", line 54, in wrapped_view
    return view_func(*args, **kwargs)
  File "/Users/kevindeems/Desktop/codingTests/python_learning/dog_server/dog_info/resources/router.py", line 83, in dispatch
    return handler_method(request, model, **kwargs)
TypeError: post() missing 1 required positional argument: 'data'
2018-08-03 17:35:16,001 [WARNING] django.request: Not Found: /api/v1/dog/90f38019-11e7-4531-9cec-a53f8c310600
