2018-07-29 12:41:00,347 [WARNING] django.request: Not Found: /favicon.ico
2018-07-29 16:07:46,615 [WARNING] django.request: Not Found: /favicon.ico
2018-07-29 16:30:56,708 [WARNING] django.request: Not Found: /api/v1/get_dog/7b49bbc6-d87b-42ce-87d5-fa512c2855f1
2018-07-29 16:31:07,709 [WARNING] django.request: Not Found: /api/v1/get_dog/7b49bbc6-d87b-42ce-87d5-fa512c2855f
2018-07-29 16:48:05,504 [WARNING] django.request: Not Found: /api/v1/get_dog/7b49bbc6-d87b-42ce-87d5-fa512c2855f2018-07-29 17:06:23,966 [ERROR] django.request: Internal Server Error: /api/v1/get_dog/7b49bbc6-d87b-42ce-87d5-fa512c2855f
Traceback (most recent call last):
  File "/usr/local/lib/python3.7/site-packages/django/core/handlers/exception.py", line 35, in inner
    response = get_response(request)
  File "/usr/local/lib/python3.7/site-packages/django/core/handlers/base.py", line 113, in _get_response
    resolver_match = resolver.resolve(request.path_info)
  File "/usr/local/lib/python3.7/site-packages/django/urls/resolvers.py", line 527, in resolve
    raise Resolver404({'tried': tried, 'path': new_path})
django.urls.exceptions.Resolver404: {'tried': [[<URLResolver <URLPattern list> (admin:admin) 'admin/'>], [<URLPattern 'api/v1/get_dog/<uuid:id>'>], [<URLPattern 'api/v1/create_user'>]], 'path': 'api/v1/get_dog/7b49bbc6-d87b-42ce-87d5-fa512c2855f'}

During handling of the above exception, another exception occurred:

Traceback (most recent call last):
  File "/usr/local/lib/python3.7/site-packages/django/core/handlers/exception.py", line 99, in get_exception_response
    response = callback(request, **dict(param_dict, exception=exception))
TypeError: handler404() got an unexpected keyword argument 'exception'
2018-07-29 17:08:30,691 [ERROR] django.request: Internal Server Error: /api/v1/get_dog/7b49bbc6-d87b-42ce-87d5-fa512c2855f
Traceback (most recent call last):
  File "/usr/local/lib/python3.7/site-packages/django/core/handlers/exception.py", line 35, in inner
    response = get_response(request)
  File "/usr/local/lib/python3.7/site-packages/django/core/handlers/base.py", line 113, in _get_response
    resolver_match = resolver.resolve(request.path_info)
  File "/usr/local/lib/python3.7/site-packages/django/urls/resolvers.py", line 527, in resolve
    raise Resolver404({'tried': tried, 'path': new_path})
django.urls.exceptions.Resolver404: {'tried': [[<URLResolver <URLPattern list> (admin:admin) 'admin/'>], [<URLPattern 'api/v1/get_dog/<uuid:id>'>], [<URLPattern 'api/v1/create_user'>]], 'path': 'api/v1/get_dog/7b49bbc6-d87b-42ce-87d5-fa512c2855f'}

During handling of the above exception, another exception occurred:

Traceback (most recent call last):
  File "/usr/local/lib/python3.7/site-packages/django/core/handlers/exception.py", line 99, in get_exception_response
    response = callback(request, **dict(param_dict, exception=exception))
TypeError: handler404() got an unexpected keyword argument 'exception'
2018-07-29 17:09:00,104 [ERROR] django.request: Internal Server Error: /api/v1/get_dog/7b49bbc6-d87b-42ce-87d5-fa512c2855f
Traceback (most recent call last):
  File "/usr/local/lib/python3.7/site-packages/django/core/handlers/exception.py", line 35, in inner
    response = get_response(request)
  File "/usr/local/lib/python3.7/site-packages/django/core/handlers/base.py", line 113, in _get_response
    resolver_match = resolver.resolve(request.path_info)
  File "/usr/local/lib/python3.7/site-packages/django/urls/resolvers.py", line 527, in resolve
    raise Resolver404({'tried': tried, 'path': new_path})
django.urls.exceptions.Resolver404: {'tried': [[<URLResolver <URLPattern list> (admin:admin) 'admin/'>], [<URLPattern 'api/v1/get_dog/<uuid:id>'>], [<URLPattern 'api/v1/create_user'>]], 'path': 'api/v1/get_dog/7b49bbc6-d87b-42ce-87d5-fa512c2855f'}

During handling of the above exception, another exception occurred:

Traceback (most recent call last):
  File "/usr/local/lib/python3.7/site-packages/django/core/handlers/exception.py", line 99, in get_exception_response
    response = callback(request, **dict(param_dict, exception=exception))
TypeError: handler404() got an unexpected keyword argument 'exception'
2018-07-29 17:19:42,538 [ERROR] django.request: Internal Server Error: /api/v1/get_dog/7b49bbc6-d87b-42ce-87d5-fa512c2855f
Traceback (most recent call last):
  File "/usr/local/lib/python3.7/site-packages/django/core/handlers/exception.py", line 35, in inner
    response = get_response(request)
  File "/usr/local/lib/python3.7/site-packages/django/core/handlers/base.py", line 113, in _get_response
    resolver_match = resolver.resolve(request.path_info)
  File "/usr/local/lib/python3.7/site-packages/django/urls/resolvers.py", line 527, in resolve
    raise Resolver404({'tried': tried, 'path': new_path})
django.urls.exceptions.Resolver404: {'tried': [[<URLResolver <URLPattern list> (admin:admin) 'admin/'>], [<URLPattern 'api/v1/get_dog/<uuid:id>'>], [<URLPattern 'api/v1/create_user'>]], 'path': 'api/v1/get_dog/7b49bbc6-d87b-42ce-87d5-fa512c2855f'}

During handling of the above exception, another exception occurred:

Traceback (most recent call last):
  File "/usr/local/lib/python3.7/site-packages/django/core/handlers/exception.py", line 99, in get_exception_response
    response = callback(request, **dict(param_dict, exception=exception))
TypeError: handler404() missing 1 required positional argument: 'template'
2018-07-29 17:23:59,042 [ERROR] django.request: Internal Server Error: /api/v1/get_dog/7b49bbc6-d87b-42ce-87d5-fa512c2855f
Traceback (most recent call last):
  File "/usr/local/lib/python3.7/site-packages/django/core/handlers/exception.py", line 35, in inner
    response = get_response(request)
  File "/usr/local/lib/python3.7/site-packages/django/core/handlers/base.py", line 113, in _get_response
    resolver_match = resolver.resolve(request.path_info)
  File "/usr/local/lib/python3.7/site-packages/django/urls/resolvers.py", line 527, in resolve
    raise Resolver404({'tried': tried, 'path': new_path})
django.urls.exceptions.Resolver404: {'tried': [[<URLResolver <URLPattern list> (admin:admin) 'admin/'>], [<URLPattern 'api/v1/get_dog/<uuid:id>'>], [<URLPattern 'api/v1/create_user'>]], 'path': 'api/v1/get_dog/7b49bbc6-d87b-42ce-87d5-fa512c2855f'}

During handling of the above exception, another exception occurred:

Traceback (most recent call last):
  File "/usr/local/lib/python3.7/site-packages/django/core/handlers/exception.py", line 99, in get_exception_response
    response = callback(request, **dict(param_dict, exception=exception))
TypeError: handler404() got an unexpected keyword argument 'exception'
2018-07-29 17:24:55,087 [WARNING] django.request: Not Found: /api/v1/get_dog/7b49bbc6-d87b-42ce-87d5-fa512c2855f
2018-07-29 17:25:52,525 [WARNING] django.request: Not Found: /api/v1/get_dog/7b49bbc6-d87b-42ce-87d5-fa512c2855f
2018-07-29 17:30:06,899 [ERROR] django.request: Internal Server Error: /api/v1/get_dog/7b49bbc6-d87b-42ce-87d5-fa512c2855f
Traceback (most recent call last):
  File "/usr/local/lib/python3.7/site-packages/django/core/handlers/exception.py", line 35, in inner
    response = get_response(request)
  File "/usr/local/lib/python3.7/site-packages/django/core/handlers/base.py", line 113, in _get_response
    resolver_match = resolver.resolve(request.path_info)
  File "/usr/local/lib/python3.7/site-packages/django/urls/resolvers.py", line 527, in resolve
    raise Resolver404({'tried': tried, 'path': new_path})
django.urls.exceptions.Resolver404: {'tried': [[<URLResolver <URLPattern list> (admin:admin) 'admin/'>], [<URLPattern 'api/v1/get_dog/<uuid:id>'>], [<URLPattern 'api/v1/create_user'>]], 'path': 'api/v1/get_dog/7b49bbc6-d87b-42ce-87d5-fa512c2855f'}

During handling of the above exception, another exception occurred:

Traceback (most recent call last):
  File "/usr/local/lib/python3.7/site-packages/django/core/handlers/exception.py", line 98, in get_exception_response
    callback, param_dict = resolver.resolve_error_handler(status_code)
  File "/usr/local/lib/python3.7/site-packages/django/urls/resolvers.py", line 559, in resolve_error_handler
    return get_callable(callback), {}
  File "/usr/local/lib/python3.7/site-packages/django/urls/utils.py", line 28, in get_callable
    mod = import_module(mod_name)
  File "/usr/local/Cellar/python/3.7.0/Frameworks/Python.framework/Versions/3.7/lib/python3.7/importlib/__init__.py", line 127, in import_module
    return _bootstrap._gcd_import(name[level:], package, level)
  File "<frozen importlib._bootstrap>", line 1006, in _gcd_import
  File "<frozen importlib._bootstrap>", line 983, in _find_and_load
  File "<frozen importlib._bootstrap>", line 967, in _find_and_load_unlocked
  File "<frozen importlib._bootstrap>", line 677, in _load_unlocked
  File "<frozen importlib._bootstrap_external>", line 724, in exec_module
  File "<frozen importlib._bootstrap_external>", line 860, in get_code
  File "<frozen importlib._bootstrap_external>", line 791, in source_to_code
  File "<frozen importlib._bootstrap>", line 219, in _call_with_frames_removed
  File "/Users/kevindeems/Desktop/codingTests/python_learning/dog_server/dog_info/errors.py", line 27
    log_msg = "Status: %s -- Exception: %s -- Ip: %s" %
                                                       ^
SyntaxError: invalid syntax
2018-07-29 17:32:04,671 [ERROR] django.request: Internal Server Error: /api/v1/get_dog/7b49bbc6-d87b-42ce-87d5-fa512c2855f
Traceback (most recent call last):
  File "/usr/local/lib/python3.7/site-packages/django/core/handlers/exception.py", line 35, in inner
    response = get_response(request)
  File "/usr/local/lib/python3.7/site-packages/django/core/handlers/base.py", line 113, in _get_response
    resolver_match = resolver.resolve(request.path_info)
  File "/usr/local/lib/python3.7/site-packages/django/urls/resolvers.py", line 527, in resolve
    raise Resolver404({'tried': tried, 'path': new_path})
django.urls.exceptions.Resolver404: {'tried': [[<URLResolver <URLPattern list> (admin:admin) 'admin/'>], [<URLPattern 'api/v1/get_dog/<uuid:id>'>], [<URLPattern 'api/v1/create_user'>]], 'path': 'api/v1/get_dog/7b49bbc6-d87b-42ce-87d5-fa512c2855f'}

During handling of the above exception, another exception occurred:

Traceback (most recent call last):
  File "/usr/local/lib/python3.7/site-packages/django/core/handlers/exception.py", line 99, in get_exception_response
    response = callback(request, **dict(param_dict, exception=exception))
  File "/Users/kevindeems/Desktop/codingTests/python_learning/dog_server/dog_info/errors.py", line 36, in handler404
    return ErrorHandler(404, request, msg).handle()
  File "/Users/kevindeems/Desktop/codingTests/python_learning/dog_server/dog_info/errors.py", line 30, in handle
    return JsonResponse(err, status=self.status, json_dumps_params={"indent": 2})
  File "/usr/local/lib/python3.7/site-packages/django/http/response.py", line 509, in __init__
    data = json.dumps(data, cls=encoder, **json_dumps_params)
  File "/usr/local/Cellar/python/3.7.0/Frameworks/Python.framework/Versions/3.7/lib/python3.7/json/__init__.py", line 238, in dumps
    **kw).encode(obj)
  File "/usr/local/Cellar/python/3.7.0/Frameworks/Python.framework/Versions/3.7/lib/python3.7/json/encoder.py", line 201, in encode
    chunks = list(chunks)
  File "/usr/local/Cellar/python/3.7.0/Frameworks/Python.framework/Versions/3.7/lib/python3.7/json/encoder.py", line 431, in _iterencode
    yield from _iterencode_dict(o, _current_indent_level)
  File "/usr/local/Cellar/python/3.7.0/Frameworks/Python.framework/Versions/3.7/lib/python3.7/json/encoder.py", line 405, in _iterencode_dict
    yield from chunks
  File "/usr/local/Cellar/python/3.7.0/Frameworks/Python.framework/Versions/3.7/lib/python3.7/json/encoder.py", line 405, in _iterencode_dict
    yield from chunks
  File "/usr/local/Cellar/python/3.7.0/Frameworks/Python.framework/Versions/3.7/lib/python3.7/json/encoder.py", line 325, in _iterencode_list
    yield from chunks
  File "/usr/local/Cellar/python/3.7.0/Frameworks/Python.framework/Versions/3.7/lib/python3.7/json/encoder.py", line 325, in _iterencode_list
    yield from chunks
  File "/usr/local/Cellar/python/3.7.0/Frameworks/Python.framework/Versions/3.7/lib/python3.7/json/encoder.py", line 438, in _iterencode
    o = _default(o)
  File "/usr/local/lib/python3.7/site-packages/django/core/serializers/json.py", line 104, in default
    return super().default(o)
  File "/usr/local/Cellar/python/3.7.0/Frameworks/Python.framework/Versions/3.7/lib/python3.7/json/encoder.py", line 179, in default
    raise TypeError(f'Object of type {o.__class__.__name__} '
TypeError: Object of type URLResolver is not JSON serializable
2018-07-29 17:33:49,402 [ERROR] django.request: Internal Server Error: /api/v1/get_dog/7b49bbc6-d87b-42ce-87d5-fa512c2855f
Traceback (most recent call last):
  File "/usr/local/lib/python3.7/site-packages/django/core/handlers/exception.py", line 35, in inner
    response = get_response(request)
  File "/usr/local/lib/python3.7/site-packages/django/core/handlers/base.py", line 113, in _get_response
    resolver_match = resolver.resolve(request.path_info)
  File "/usr/local/lib/python3.7/site-packages/django/urls/resolvers.py", line 527, in resolve
    raise Resolver404({'tried': tried, 'path': new_path})
django.urls.exceptions.Resolver404: {'tried': [[<URLResolver <URLPattern list> (admin:admin) 'admin/'>], [<URLPattern 'api/v1/get_dog/<uuid:id>'>], [<URLPattern 'api/v1/create_user'>]], 'path': 'api/v1/get_dog/7b49bbc6-d87b-42ce-87d5-fa512c2855f'}

During handling of the above exception, another exception occurred:

Traceback (most recent call last):
  File "/usr/local/lib/python3.7/site-packages/django/core/handlers/exception.py", line 99, in get_exception_response
    response = callback(request, **dict(param_dict, exception=exception))
  File "/Users/kevindeems/Desktop/codingTests/python_learning/dog_server/dog_info/errors.py", line 36, in handler404
    return ErrorHandler(404, request, msg).handle()
  File "/Users/kevindeems/Desktop/codingTests/python_learning/dog_server/dog_info/errors.py", line 30, in handle
    return JsonResponse(err, status=self.status, json_dumps_params={"indent": 2})
  File "/usr/local/lib/python3.7/site-packages/django/http/response.py", line 509, in __init__
    data = json.dumps(data, cls=encoder, **json_dumps_params)
  File "/usr/local/Cellar/python/3.7.0/Frameworks/Python.framework/Versions/3.7/lib/python3.7/json/__init__.py", line 238, in dumps
    **kw).encode(obj)
  File "/usr/local/Cellar/python/3.7.0/Frameworks/Python.framework/Versions/3.7/lib/python3.7/json/encoder.py", line 201, in encode
    chunks = list(chunks)
  File "/usr/local/Cellar/python/3.7.0/Frameworks/Python.framework/Versions/3.7/lib/python3.7/json/encoder.py", line 431, in _iterencode
    yield from _iterencode_dict(o, _current_indent_level)
  File "/usr/local/Cellar/python/3.7.0/Frameworks/Python.framework/Versions/3.7/lib/python3.7/json/encoder.py", line 405, in _iterencode_dict
    yield from chunks
  File "/usr/local/Cellar/python/3.7.0/Frameworks/Python.framework/Versions/3.7/lib/python3.7/json/encoder.py", line 405, in _iterencode_dict
    yield from chunks
  File "/usr/local/Cellar/python/3.7.0/Frameworks/Python.framework/Versions/3.7/lib/python3.7/json/encoder.py", line 325, in _iterencode_list
    yield from chunks
  File "/usr/local/Cellar/python/3.7.0/Frameworks/Python.framework/Versions/3.7/lib/python3.7/json/encoder.py", line 325, in _iterencode_list
    yield from chunks
  File "/usr/local/Cellar/python/3.7.0/Frameworks/Python.framework/Versions/3.7/lib/python3.7/json/encoder.py", line 438, in _iterencode
    o = _default(o)
  File "/usr/local/lib/python3.7/site-packages/django/core/serializers/json.py", line 104, in default
    return super().default(o)
  File "/usr/local/Cellar/python/3.7.0/Frameworks/Python.framework/Versions/3.7/lib/python3.7/json/encoder.py", line 179, in default
    raise TypeError(f'Object of type {o.__class__.__name__} '
TypeError: Object of type URLResolver is not JSON serializable
2018-07-29 17:34:31,854 [WARNING] django.request: Not Found: /api/v1/get_dog/7b49bbc6-d87b-42ce-87d5-fa512c2855f
2018-07-29 17:36:31,767 [WARNING] django.request: Not Found: /api/v1/get_dog/7b49bbc6-d87b-42ce-87d5-fa512c2855f
2018-07-29 17:36:46,009 [WARNING] django.request: Not Found: /api/v1/get_dog/7b49bbc6-d87b-42ce-87d5-fa512c2855f
2018-07-29 17:37:23,191 [ERROR] django.request: Internal Server Error: /api/v1/get_dog/7b49bbc6-d87b-42ce-87d5-fa512c2855f
Traceback (most recent call last):
  File "/usr/local/lib/python3.7/site-packages/django/core/handlers/exception.py", line 35, in inner
    response = get_response(request)
  File "/usr/local/lib/python3.7/site-packages/django/core/handlers/base.py", line 113, in _get_response
    resolver_match = resolver.resolve(request.path_info)
  File "/usr/local/lib/python3.7/site-packages/django/urls/resolvers.py", line 527, in resolve
    raise Resolver404({'tried': tried, 'path': new_path})
django.urls.exceptions.Resolver404: {'tried': [[<URLResolver <URLPattern list> (admin:admin) 'admin/'>], [<URLPattern 'api/v1/get_dog/<uuid:id>'>], [<URLPattern 'api/v1/create_user'>]], 'path': 'api/v1/get_dog/7b49bbc6-d87b-42ce-87d5-fa512c2855f'}

During handling of the above exception, another exception occurred:

Traceback (most recent call last):
  File "/usr/local/lib/python3.7/site-packages/django/core/handlers/exception.py", line 99, in get_exception_response
    response = callback(request, **dict(param_dict, exception=exception))
  File "/Users/kevindeems/Desktop/codingTests/python_learning/dog_server/dog_info/errors.py", line 36, in handler404
    return ErrorHandler(404, request, msg).handle()
  File "/Users/kevindeems/Desktop/codingTests/python_learning/dog_server/dog_info/errors.py", line 30, in handle
    return JsonResponse(err, status=self.status, json_dumps_params={"indent": 2})
  File "/usr/local/lib/python3.7/site-packages/django/http/response.py", line 509, in __init__
    data = json.dumps(data, cls=encoder, **json_dumps_params)
  File "/usr/local/Cellar/python/3.7.0/Frameworks/Python.framework/Versions/3.7/lib/python3.7/json/__init__.py", line 238, in dumps
    **kw).encode(obj)
  File "/usr/local/Cellar/python/3.7.0/Frameworks/Python.framework/Versions/3.7/lib/python3.7/json/encoder.py", line 201, in encode
    chunks = list(chunks)
  File "/usr/local/Cellar/python/3.7.0/Frameworks/Python.framework/Versions/3.7/lib/python3.7/json/encoder.py", line 431, in _iterencode
    yield from _iterencode_dict(o, _current_indent_level)
  File "/usr/local/Cellar/python/3.7.0/Frameworks/Python.framework/Versions/3.7/lib/python3.7/json/encoder.py", line 405, in _iterencode_dict
    yield from chunks
  File "/usr/local/Cellar/python/3.7.0/Frameworks/Python.framework/Versions/3.7/lib/python3.7/json/encoder.py", line 405, in _iterencode_dict
    yield from chunks
  File "/usr/local/Cellar/python/3.7.0/Frameworks/Python.framework/Versions/3.7/lib/python3.7/json/encoder.py", line 325, in _iterencode_list
    yield from chunks
  File "/usr/local/Cellar/python/3.7.0/Frameworks/Python.framework/Versions/3.7/lib/python3.7/json/encoder.py", line 325, in _iterencode_list
    yield from chunks
  File "/usr/local/Cellar/python/3.7.0/Frameworks/Python.framework/Versions/3.7/lib/python3.7/json/encoder.py", line 438, in _iterencode
    o = _default(o)
  File "/usr/local/lib/python3.7/site-packages/django/core/serializers/json.py", line 104, in default
    return super().default(o)
  File "/usr/local/Cellar/python/3.7.0/Frameworks/Python.framework/Versions/3.7/lib/python3.7/json/encoder.py", line 179, in default
    raise TypeError(f'Object of type {o.__class__.__name__} '
TypeError: Object of type URLResolver is not JSON serializable
2018-07-29 17:38:37,459 [WARNING] django.request: Not Found: /api/v1/get_dog/7b49bbc6-d87b-42ce-87d5-fa512c2855f
2018-07-29 17:42:23,711 [ERROR] django.request: Internal Server Error: /api/v1/get_dog/7b49bbc6-d87b-42ce-87d5-fa512c2855f
Traceback (most recent call last):
  File "/usr/local/lib/python3.7/site-packages/django/core/handlers/exception.py", line 35, in inner
    response = get_response(request)
  File "/usr/local/lib/python3.7/site-packages/django/core/handlers/base.py", line 113, in _get_response
    resolver_match = resolver.resolve(request.path_info)
  File "/usr/local/lib/python3.7/site-packages/django/urls/resolvers.py", line 527, in resolve
    raise Resolver404({'tried': tried, 'path': new_path})
django.urls.exceptions.Resolver404: {'tried': [[<URLResolver <URLPattern list> (admin:admin) 'admin/'>], [<URLPattern 'api/v1/get_dog/<uuid:id>'>], [<URLPattern 'api/v1/create_user'>]], 'path': 'api/v1/get_dog/7b49bbc6-d87b-42ce-87d5-fa512c2855f'}

During handling of the above exception, another exception occurred:

Traceback (most recent call last):
  File "/usr/local/lib/python3.7/site-packages/django/core/handlers/exception.py", line 99, in get_exception_response
    response = callback(request, **dict(param_dict, exception=exception))
  File "/Users/kevindeems/Desktop/codingTests/python_learning/dog_server/dog_info/errors.py", line 40, in handler404
    return ErrorHandler(404, request, msg.path).handle()
AttributeError: 'dict' object has no attribute 'path'
2018-07-29 17:44:59,601 [WARNING] django.request: Not Found: /api/v1/get_dog/7b49bbc6-d87b-42ce-87d5-fa512c2855f
2018-07-29 17:46:13,472 [WARNING] django.request: Not Found: /api/v1/get_dog/7b49bbc6-d87b-42ce-87d5-fa512c2855f
2018-07-29 17:46:41,320 [WARNING] django.request: Not Found: /static/admin/js/vendor/jquery/jquery.min.js
2018-07-29 17:46:41,326 [WARNING] django.request: Not Found: /static/admin/js/actions.min.js
2018-07-29 17:46:41,333 [WARNING] django.request: Not Found: /static/admin/js/prepopulate.min.js
2018-07-29 17:46:41,339 [WARNING] django.request: Not Found: /static/admin/js/vendor/xregexp/xregexp.min.js
2018-07-29 18:22:36,606 [WARNING] django.request: Not Found: /static/admin/js/vendor/jquery/jquery.min.js
2018-07-29 18:22:36,609 [WARNING] django.request: Not Found: /static/admin/js/actions.min.js
2018-07-29 18:22:36,617 [WARNING] django.request: Not Found: /static/admin/js/vendor/xregexp/xregexp.min.js
2018-07-29 18:22:36,620 [WARNING] django.request: Not Found: /static/admin/js/prepopulate.min.js
2018-07-29 18:22:36,763 [WARNING] django.request: Not Found: /static/admin/js/vendor/jquery/jquery.min.js
2018-07-29 18:22:36,771 [WARNING] django.request: Not Found: /static/admin/js/actions.min.js
2018-07-29 18:22:36,778 [WARNING] django.request: Not Found: /static/admin/js/prepopulate.min.js
2018-07-29 18:22:36,784 [WARNING] django.request: Not Found: /static/admin/js/vendor/xregexp/xregexp.min.js
2018-07-29 19:01:26,559 [ERROR] django.request: Internal Server Error: /api/v1/get_dog/7b49bbc6-d87b-42ce-87d5-fa512c2855f0
Traceback (most recent call last):
  File "/usr/local/lib/python3.7/site-packages/django/core/handlers/exception.py", line 35, in inner
    response = get_response(request)
  File "/usr/local/lib/python3.7/site-packages/django/core/handlers/base.py", line 139, in _get_response
    "returned None instead." % (callback.__module__, view_name)
ValueError: The view dog_info.views.method.__call__ didn't return an HttpResponse object. It returned None instead.
